2018-08-31 13:49:41,581 ERROR: Exception on /index [GET] [in /home/john/Desktop/microblog/venv/lib/python3.6/site-packages/flask/app.py:1761]
Traceback (most recent call last):
  File "/home/john/Desktop/microblog/venv/lib/python3.6/site-packages/flask/app.py", line 2292, in wsgi_app
    response = self.full_dispatch_request()
  File "/home/john/Desktop/microblog/venv/lib/python3.6/site-packages/flask/app.py", line 1815, in full_dispatch_request
    rv = self.handle_user_exception(e)
  File "/home/john/Desktop/microblog/venv/lib/python3.6/site-packages/flask/app.py", line 1718, in handle_user_exception
    reraise(exc_type, exc_value, tb)
  File "/home/john/Desktop/microblog/venv/lib/python3.6/site-packages/flask/_compat.py", line 35, in reraise
    raise value
  File "/home/john/Desktop/microblog/venv/lib/python3.6/site-packages/flask/app.py", line 1813, in full_dispatch_request
    rv = self.dispatch_request()
  File "/home/john/Desktop/microblog/venv/lib/python3.6/site-packages/flask/app.py", line 1799, in dispatch_request
    return self.view_functions[rule.endpoint](**req.view_args)
  File "/home/john/Desktop/microblog/venv/lib/python3.6/site-packages/flask_login/utils.py", line 261, in decorated_view
    return func(*args, **kwargs)
  File "/home/john/Desktop/microblog/app/routes.py", line 37, in index
    posts=posts)
  File "/home/john/Desktop/microblog/venv/lib/python3.6/site-packages/flask/templating.py", line 135, in render_template
    context, ctx.app)
  File "/home/john/Desktop/microblog/venv/lib/python3.6/site-packages/flask/templating.py", line 117, in _render
    rv = template.render(context)
  File "/home/john/Desktop/microblog/venv/lib/python3.6/site-packages/jinja2/asyncsupport.py", line 76, in render
    return original_render(self, *args, **kwargs)
  File "/home/john/Desktop/microblog/venv/lib/python3.6/site-packages/jinja2/environment.py", line 1008, in render
    return self.environment.handle_exception(exc_info, True)
  File "/home/john/Desktop/microblog/venv/lib/python3.6/site-packages/jinja2/environment.py", line 780, in handle_exception
    reraise(exc_type, exc_value, tb)
  File "/home/john/Desktop/microblog/venv/lib/python3.6/site-packages/jinja2/_compat.py", line 37, in reraise
    raise value.with_traceback(tb)
  File "/home/john/Desktop/microblog/app/templates/index.html", line 1, in top-level template code
    {% extends "base.html" %}
  File "/home/john/Desktop/microblog/app/templates/base.html", line 31, in top-level template code
    {% block content %}{% endblock %}
  File "/home/john/Desktop/microblog/app/templates/index.html", line 19, in block "content"
    {% include '_post.html' %}
  File "/home/john/Desktop/microblog/app/templates/_post.html", line 3, in top-level template code
    <td><img src="{{ post.author.avatar(36) }}"></td>
jinja2.exceptions.UndefinedError: 'dict object' has no attribute 'avatar'
2018-08-31 13:49:42,836 ERROR: Exception on /index [GET] [in /home/john/Desktop/microblog/venv/lib/python3.6/site-packages/flask/app.py:1761]
Traceback (most recent call last):
  File "/home/john/Desktop/microblog/venv/lib/python3.6/site-packages/flask/app.py", line 2292, in wsgi_app
    response = self.full_dispatch_request()
  File "/home/john/Desktop/microblog/venv/lib/python3.6/site-packages/flask/app.py", line 1815, in full_dispatch_request
    rv = self.handle_user_exception(e)
  File "/home/john/Desktop/microblog/venv/lib/python3.6/site-packages/flask/app.py", line 1718, in handle_user_exception
    reraise(exc_type, exc_value, tb)
  File "/home/john/Desktop/microblog/venv/lib/python3.6/site-packages/flask/_compat.py", line 35, in reraise
    raise value
  File "/home/john/Desktop/microblog/venv/lib/python3.6/site-packages/flask/app.py", line 1813, in full_dispatch_request
    rv = self.dispatch_request()
  File "/home/john/Desktop/microblog/venv/lib/python3.6/site-packages/flask/app.py", line 1799, in dispatch_request
    return self.view_functions[rule.endpoint](**req.view_args)
  File "/home/john/Desktop/microblog/venv/lib/python3.6/site-packages/flask_login/utils.py", line 261, in decorated_view
    return func(*args, **kwargs)
  File "/home/john/Desktop/microblog/app/routes.py", line 37, in index
    posts=posts)
  File "/home/john/Desktop/microblog/venv/lib/python3.6/site-packages/flask/templating.py", line 135, in render_template
    context, ctx.app)
  File "/home/john/Desktop/microblog/venv/lib/python3.6/site-packages/flask/templating.py", line 117, in _render
    rv = template.render(context)
  File "/home/john/Desktop/microblog/venv/lib/python3.6/site-packages/jinja2/asyncsupport.py", line 76, in render
    return original_render(self, *args, **kwargs)
  File "/home/john/Desktop/microblog/venv/lib/python3.6/site-packages/jinja2/environment.py", line 1008, in render
    return self.environment.handle_exception(exc_info, True)
  File "/home/john/Desktop/microblog/venv/lib/python3.6/site-packages/jinja2/environment.py", line 780, in handle_exception
    reraise(exc_type, exc_value, tb)
  File "/home/john/Desktop/microblog/venv/lib/python3.6/site-packages/jinja2/_compat.py", line 37, in reraise
    raise value.with_traceback(tb)
  File "/home/john/Desktop/microblog/app/templates/index.html", line 1, in top-level template code
    {% extends "base.html" %}
  File "/home/john/Desktop/microblog/app/templates/base.html", line 31, in top-level template code
    {% block content %}{% endblock %}
  File "/home/john/Desktop/microblog/app/templates/index.html", line 19, in block "content"
    {% include '_post.html' %}
  File "/home/john/Desktop/microblog/app/templates/_post.html", line 3, in top-level template code
    <td><img src="{{ post.author.avatar(36) }}"></td>
jinja2.exceptions.UndefinedError: 'dict object' has no attribute 'avatar'
2018-08-31 13:50:12,952 INFO: Microblog startup [in /home/john/Desktop/microblog/app/__init__.py:44]
2018-08-31 13:52:27,965 INFO: Microblog startup [in /home/john/Desktop/microblog/app/__init__.py:44]
2018-08-31 13:56:17,299 INFO: Microblog startup [in /home/john/Desktop/microblog/app/__init__.py:44]
2018-08-31 13:58:32,147 INFO: Microblog startup [in /home/john/Desktop/microblog/app/__init__.py:44]
2018-09-04 10:03:14,881 INFO: Microblog startup [in /home/john/Desktop/microblog/app/__init__.py:44]
2018-09-04 10:03:25,286 INFO: Microblog startup [in /home/john/Desktop/microblog/app/__init__.py:44]
2018-09-04 10:11:42,554 INFO: Microblog startup [in /home/john/Desktop/microblog/app/__init__.py:44]
2018-09-04 10:11:44,499 ERROR: Exception on /explore [GET] [in /home/john/Desktop/microblog/venv/lib/python3.6/site-packages/flask/app.py:1761]
Traceback (most recent call last):
  File "/home/john/Desktop/microblog/venv/lib/python3.6/site-packages/flask/app.py", line 2292, in wsgi_app
    response = self.full_dispatch_request()
  File "/home/john/Desktop/microblog/venv/lib/python3.6/site-packages/flask/app.py", line 1815, in full_dispatch_request
    rv = self.handle_user_exception(e)
  File "/home/john/Desktop/microblog/venv/lib/python3.6/site-packages/flask/app.py", line 1718, in handle_user_exception
    reraise(exc_type, exc_value, tb)
  File "/home/john/Desktop/microblog/venv/lib/python3.6/site-packages/flask/_compat.py", line 35, in reraise
    raise value
  File "/home/john/Desktop/microblog/venv/lib/python3.6/site-packages/flask/app.py", line 1813, in full_dispatch_request
    rv = self.dispatch_request()
  File "/home/john/Desktop/microblog/venv/lib/python3.6/site-packages/flask/app.py", line 1799, in dispatch_request
    return self.view_functions[rule.endpoint](**req.view_args)
  File "/home/john/Desktop/microblog/venv/lib/python3.6/site-packages/flask_login/utils.py", line 261, in decorated_view
    return func(*args, **kwargs)
  File "/home/john/Desktop/microblog/app/routes.py", line 129, in explore
    page, app.config['POSTS_PER_PAGE', False])
KeyError: ('POSTS_PER_PAGE', False)
2018-09-04 10:13:40,054 INFO: Microblog startup [in /home/john/Desktop/microblog/app/__init__.py:44]
