2018-08-31 13:27:16,226 ERROR: Exception on /index [GET] [in /home/john/Desktop/microblog/venv/lib/python3.6/site-packages/flask/app.py:1761]
Traceback (most recent call last):
  File "/home/john/Desktop/microblog/venv/lib/python3.6/site-packages/flask/app.py", line 2292, in wsgi_app
    response = self.full_dispatch_request()
  File "/home/john/Desktop/microblog/venv/lib/python3.6/site-packages/flask/app.py", line 1815, in full_dispatch_request
    rv = self.handle_user_exception(e)
  File "/home/john/Desktop/microblog/venv/lib/python3.6/site-packages/flask/app.py", line 1718, in handle_user_exception
    reraise(exc_type, exc_value, tb)
  File "/home/john/Desktop/microblog/venv/lib/python3.6/site-packages/flask/_compat.py", line 35, in reraise
    raise value
  File "/home/john/Desktop/microblog/venv/lib/python3.6/site-packages/flask/app.py", line 1813, in full_dispatch_request
    rv = self.dispatch_request()
  File "/home/john/Desktop/microblog/venv/lib/python3.6/site-packages/flask/app.py", line 1799, in dispatch_request
    return self.view_functions[rule.endpoint](**req.view_args)
  File "/home/john/Desktop/microblog/venv/lib/python3.6/site-packages/flask_login/utils.py", line 261, in decorated_view
    return func(*args, **kwargs)
  File "/home/john/Desktop/microblog/app/routes.py", line 31, in index
    posts=posts)
  File "/home/john/Desktop/microblog/venv/lib/python3.6/site-packages/flask/templating.py", line 135, in render_template
    context, ctx.app)
  File "/home/john/Desktop/microblog/venv/lib/python3.6/site-packages/flask/templating.py", line 117, in _render
    rv = template.render(context)
  File "/home/john/Desktop/microblog/venv/lib/python3.6/site-packages/jinja2/asyncsupport.py", line 76, in render
    return original_render(self, *args, **kwargs)
  File "/home/john/Desktop/microblog/venv/lib/python3.6/site-packages/jinja2/environment.py", line 1008, in render
    return self.environment.handle_exception(exc_info, True)
  File "/home/john/Desktop/microblog/venv/lib/python3.6/site-packages/jinja2/environment.py", line 780, in handle_exception
    reraise(exc_type, exc_value, tb)
  File "/home/john/Desktop/microblog/venv/lib/python3.6/site-packages/jinja2/_compat.py", line 37, in reraise
    raise value.with_traceback(tb)
  File "/home/john/Desktop/microblog/app/templates/index.html", line 1, in top-level template code
    {% extends "base.html" %}
  File "/home/john/Desktop/microblog/app/templates/base.html", line 31, in top-level template code
    {% block content %}{% endblock %}
  File "/home/john/Desktop/microblog/app/templates/index.html", line 18, in block "content"
    {% for post in posts %}
TypeError: 'Pagination' object is not iterable
2018-08-31 13:27:30,115 INFO: Microblog startup [in /home/john/Desktop/microblog/app/__init__.py:44]
2018-08-31 13:31:31,747 INFO: Microblog startup [in /home/john/Desktop/microblog/app/__init__.py:44]
2018-08-31 13:32:41,977 INFO: Microblog startup [in /home/john/Desktop/microblog/app/__init__.py:44]
2018-08-31 13:37:26,673 INFO: Microblog startup [in /home/john/Desktop/microblog/app/__init__.py:44]
2018-08-31 13:44:26,666 INFO: Microblog startup [in /home/john/Desktop/microblog/app/__init__.py:44]
2018-08-31 13:49:27,345 INFO: Microblog startup [in /home/john/Desktop/microblog/app/__init__.py:44]
2018-08-31 13:49:30,358 ERROR: Exception on /index [GET] [in /home/john/Desktop/microblog/venv/lib/python3.6/site-packages/flask/app.py:1761]
Traceback (most recent call last):
  File "/home/john/Desktop/microblog/venv/lib/python3.6/site-packages/flask/app.py", line 2292, in wsgi_app
    response = self.full_dispatch_request()
  File "/home/john/Desktop/microblog/venv/lib/python3.6/site-packages/flask/app.py", line 1815, in full_dispatch_request
    rv = self.handle_user_exception(e)
  File "/home/john/Desktop/microblog/venv/lib/python3.6/site-packages/flask/app.py", line 1718, in handle_user_exception
    reraise(exc_type, exc_value, tb)
  File "/home/john/Desktop/microblog/venv/lib/python3.6/site-packages/flask/_compat.py", line 35, in reraise
    raise value
  File "/home/john/Desktop/microblog/venv/lib/python3.6/site-packages/flask/app.py", line 1813, in full_dispatch_request
    rv = self.dispatch_request()
  File "/home/john/Desktop/microblog/venv/lib/python3.6/site-packages/flask/app.py", line 1799, in dispatch_request
    return self.view_functions[rule.endpoint](**req.view_args)
  File "/home/john/Desktop/microblog/venv/lib/python3.6/site-packages/flask_login/utils.py", line 261, in decorated_view
    return func(*args, **kwargs)
  File "/home/john/Desktop/microblog/app/routes.py", line 37, in index
    posts=posts)
  File "/home/john/Desktop/microblog/venv/lib/python3.6/site-packages/flask/templating.py", line 135, in render_template
    context, ctx.app)
  File "/home/john/Desktop/microblog/venv/lib/python3.6/site-packages/flask/templating.py", line 117, in _render
    rv = template.render(context)
  File "/home/john/Desktop/microblog/venv/lib/python3.6/site-packages/jinja2/asyncsupport.py", line 76, in render
    return original_render(self, *args, **kwargs)
  File "/home/john/Desktop/microblog/venv/lib/python3.6/site-packages/jinja2/environment.py", line 1008, in render
    return self.environment.handle_exception(exc_info, True)
  File "/home/john/Desktop/microblog/venv/lib/python3.6/site-packages/jinja2/environment.py", line 780, in handle_exception
    reraise(exc_type, exc_value, tb)
  File "/home/john/Desktop/microblog/venv/lib/python3.6/site-packages/jinja2/_compat.py", line 37, in reraise
    raise value.with_traceback(tb)
  File "/home/john/Desktop/microblog/app/templates/index.html", line 1, in top-level template code
    {% extends "base.html" %}
  File "/home/john/Desktop/microblog/app/templates/base.html", line 31, in top-level template code
    {% block content %}{% endblock %}
  File "/home/john/Desktop/microblog/app/templates/index.html", line 19, in block "content"
    {% include '_post.html' %}
  File "/home/john/Desktop/microblog/app/templates/_post.html", line 3, in top-level template code
    <td><img src="{{ post.author.avatar(36) }}"></td>
jinja2.exceptions.UndefinedError: 'dict object' has no attribute 'avatar'
2018-08-31 13:49:39,967 ERROR: Exception on /index [GET] [in /home/john/Desktop/microblog/venv/lib/python3.6/site-packages/flask/app.py:1761]
Traceback (most recent call last):
  File "/home/john/Desktop/microblog/venv/lib/python3.6/site-packages/flask/app.py", line 2292, in wsgi_app
    response = self.full_dispatch_request()
  File "/home/john/Desktop/microblog/venv/lib/python3.6/site-packages/flask/app.py", line 1815, in full_dispatch_request
    rv = self.handle_user_exception(e)
  File "/home/john/Desktop/microblog/venv/lib/python3.6/site-packages/flask/app.py", line 1718, in handle_user_exception
    reraise(exc_type, exc_value, tb)
  File "/home/john/Desktop/microblog/venv/lib/python3.6/site-packages/flask/_compat.py", line 35, in reraise
    raise value
  File "/home/john/Desktop/microblog/venv/lib/python3.6/site-packages/flask/app.py", line 1813, in full_dispatch_request
    rv = self.dispatch_request()
  File "/home/john/Desktop/microblog/venv/lib/python3.6/site-packages/flask/app.py", line 1799, in dispatch_request
    return self.view_functions[rule.endpoint](**req.view_args)
  File "/home/john/Desktop/microblog/venv/lib/python3.6/site-packages/flask_login/utils.py", line 261, in decorated_view
    return func(*args, **kwargs)
  File "/home/john/Desktop/microblog/app/routes.py", line 37, in index
    posts=posts)
  File "/home/john/Desktop/microblog/venv/lib/python3.6/site-packages/flask/templating.py", line 135, in render_template
    context, ctx.app)
  File "/home/john/Desktop/microblog/venv/lib/python3.6/site-packages/flask/templating.py", line 117, in _render
    rv = template.render(context)
  File "/home/john/Desktop/microblog/venv/lib/python3.6/site-packages/jinja2/asyncsupport.py", line 76, in render
    return original_render(self, *args, **kwargs)
  File "/home/john/Desktop/microblog/venv/lib/python3.6/site-packages/jinja2/environment.py", line 1008, in render
    return self.environment.handle_exception(exc_info, True)
  File "/home/john/Desktop/microblog/venv/lib/python3.6/site-packages/jinja2/environment.py", line 780, in handle_exception
    reraise(exc_type, exc_value, tb)
  File "/home/john/Desktop/microblog/venv/lib/python3.6/site-packages/jinja2/_compat.py", line 37, in reraise
    raise value.with_traceback(tb)
  File "/home/john/Desktop/microblog/app/templates/index.html", line 1, in top-level template code
    {% extends "base.html" %}
  File "/home/john/Desktop/microblog/app/templates/base.html", line 31, in top-level template code
    {% block content %}{% endblock %}
  File "/home/john/Desktop/microblog/app/templates/index.html", line 19, in block "content"
    {% include '_post.html' %}
  File "/home/john/Desktop/microblog/app/templates/_post.html", line 3, in top-level template code
    <td><img src="{{ post.author.avatar(36) }}"></td>
jinja2.exceptions.UndefinedError: 'dict object' has no attribute 'avatar'
